Workbook

Sheet HOME

Sheet S.DATA
B1: LIBRARY MANAGEMENT SYSTEM
B6: STUDENT DATA
B7: Sr no | C7: Student name | D7: Father name | E7: Student id | F7: Course | G7: Section | H7: Contact no. | I7: Student Email | J7: CNIC no. | K7: Address | M7: Sr no | N7: Student id | O7: Student name | P7: Contact no. | Q7: Student Email
B8: 1 | C8: Ali | D8: Abid | E8: LGU-BSCS-1 | F8: BSCS | G8: C | H8: 9234567901 | I8: abde1@gmail.com | J8: 35200-0789938-1 | K8: Student address 1 | M8: 15 | N8: =VLOOKUP(M8,$B$7:$K$28,4,0) -> LGU-BSCS-15 | O8: =VLOOKUP(M8,$B$7:$K$28,2,0) -> Abdulla | P8: =VLOOKUP(M8,$B$7:$K$28,7,0) -> 9234567915 | Q8: =VLOOKUP(M8,$B$7:$K$28,8,0) -> abde1@gmail.com
B9: 2 | C9: Sana | D9: Faisal | E9: LGU-BSCS-2 | F9: BSCS | G9: C | H9: 9234567902 | I9: abde2@gmail.com | J9: 35200-0789938-2 | K9: Student address 2 | M9: 7 | N9: =VLOOKUP(M9,$B$7:$K$28,4,0) -> LGU-BSCS-7 | O9: =VLOOKUP(M9,$B$7:$K$28,2,0) -> komal | P9: =VLOOKUP(M9,$B$7:$K$28,7,0) -> 9234567907 | Q9: =VLOOKUP(M9,$B$7:$K$28,8,0) -> abde1@gmail.com
B10: 3 | C10: Fajar | D10: Sabahat | E10: LGU-BSCS-3 | F10: BSCS | G10: C | H10: 9234567903 | I10: abde1@gmail.com | J10: 35200-0789938-3 | K10: Student address 3 | M10: 8 | N10: =VLOOKUP(M10,$B$7:$K$28,4,0) -> LGU-BSCS-8 | O10: =VLOOKUP(M10,$B$7:$K$28,2,0) -> Umer | P10: =VLOOKUP(M10,$B$7:$K$28,7,0) -> 9234567908 | Q10: =VLOOKUP(M10,$B$7:$K$28,8,0) -> abde2@gmail.com
B11: 4 | C11: malaika | D11: faraz | E11: LGU-BSCS-4 | F11: BSCS | G11: C | H11: 9234567904 | I11: abde2@gmail.com | J11: 35200-0789938-4 | K11: Student address 4
B12: 5 | C12: Taha | D12: Faizan | E12: LGU-BSCS-5 | F12: BSCS | G12: C | H12: 9234567905 | I12: abde1@gmail.com | J12: 35200-0789938-5 | K12: Student address 5
B13: 6 | C13: Zoha | D13: Sufian | E13: LGU-BSCS-6 | F13: BSCS | G13: C | H13: 9234567906 | I13: abde2@gmail.com | J13: 35200-0789938-6 | K13: Student address 6
B14: 7 | C14: komal | D14: Safe | E14: LGU-BSCS-7 | F14: BSCS | G14: C | H14: 9234567907 | I14: abde1@gmail.com | J14: 35200-0789938-7 | K14: Student address 7
B15: 8 | C15: Umer | D15: Fahad | E15: LGU-BSCS-8 | F15: BSSE | G15: C | H15: 9234567908 | I15: abde2@gmail.com | J15: 35200-0789938-8 | K15: Student address 8
B16: 9 | C16: Fahad | D16: asghar | E16: LGU-BSCS-9 | F16: BSSE | G16: C | H16: 9234567909 | I16: abde1@gmail.com | J16: 35200-0789938-9 | K16: Student address 9
B17: 10 | C17: Neha | D17: Saud | E17: LGU-BSCS-10 | F17: BSSE | G17: C | H17: 9234567910 | I17: abde2@gmail.com | J17: 35200-0789948-1 | K17: Student address 10
B18: 11 | C18: Eman | D18: taha | E18: LGU-BSCS-11 | F18: BSSE | G18: C | H18: 9234567911 | I18: abde1@gmail.com | J18: 35200-0789948-2 | K18: Student address 11
B19: 12 | C19: Attiqa | D19: Ali | E19: LGU-BSCS-12 | F19: BSSE | G19: C | H19: 9234567912 | I19: abde2@gmail.com | J19: 35200-0789948-3 | K19: Student address 12
B20: 13 | C20: Zara | D20: AHSAN | E20: LGU-BSCS-13 | F20: BSSE | G20: C | H20: 9234567913 | I20: abde1@gmail.com | J20: 35200-0789948-4 | K20: Student address 13
B21: 14 | C21: zoya | D21: Umer | E21: LGU-BSCS-14 | F21: BSIT | G21: C | H21: 9234567914 | I21: abde2@gmail.com | J21: 35200-0789948-5 | K21: Student address 14
B22: 15 | C22: Abdulla | D22: Ahmad | E22: LGU-BSCS-15 | F22: BSIT | G22: C | H22: 9234567915 | I22: abde1@gmail.com | J22: 35200-0789948-6 | K22: Student address 15
... B28: 21 | C28: Farah | D28: Nasir | E28: LGU-BSCS-21 | F28: BSCS | G28: C | H28: 9234567920 | I28: abde2@gmail.com | J28: 35200-0789448-3 | K28: Student address 21

Sheet L.RECORD
B1: LIBRARIANS RECORD
B5: Sr no. | C5: Librarian ID | D5: Name | E5: CNIC no. | F5: Contact no. | G5: Email | I5: Sr no. | J5: Librarian ID | K5: Name | L5: CNIC no. | M5: Contact no. | N5: Email
B6: 1 | C6: LGU-L-1 | D6: Ali | E6: 35200-0784938-1 | F6: 92-3114718776 | G6: abde1@gmail.com | I6: 1 | J6: =VLOOKUP(I6,$B$5:$G$16,2,0) -> LGU-L-1 | K6: =VLOOKUP(I6,$B$5:$G$16,3,0) -> Ali | L6: =VLOOKUP(I6,$B$5:$G$16,4,0) -> 35200-0784938-1 | M6: =VLOOKUP(I6,$B$5:$G$16,5,0) -> 92-3114718776 | N6: =VLOOKUP(I6,$B$5:$G$16,6,0) -> abde1@gmail.com
B7: 2 | C7: LGU-L-2 | D7: Sana | E7: 35200-0789938-2 | F7: 92-3115718776 | G7: abde2@gmail.com
B8: 3 | C8: LGU-L-3 | D8: Fajar | E8: 35200-0789938-3 | F8: 92-3116718776 | G8: abde1@gmail.com
B9: 4 | C9: LGU-L-4 | D9: malaika | E9: 35200-0789938-4 | F9: 92-3117718776 | G9: abde2@gmail.com
B10: 5 | C10: LGU-L-5 | D10: Taha | E10: 35200-0789938-5 | F10: 92-3118718776 | G10: abde1@gmail.com
B11: 6 | C11: LGU-L-6 | D11: Zoha | E11: 35200-0789938-6 | F11: 92-3119718776 | G11: abde2@gmail.com
B12: 7 | C12: LGU-L-7 | D12: komal | E12: 35200-0789938-7 | F12: 92-3120718776 | G12: abde1@gmail.com
B13: 8 | C13: LGU-L-8 | D13: Umer | E13: 35200-0789938-8 | F13: 92-3121718776 | G13: abde2@gmail.com
B14: 9 | C14: LGU-L-9 | D14: Fahad | E14: 35200-0789938-9 | F14: 92-3122718776 | G14: abde1@gmail.com
B15: 10 | C15: LGU-L-10 | D15: Neha | E15: 35200-0789948-1 | F15: 92-3123718776 | G15: abde2@gmail.com
D16: Eman

Sheet BOOK INFO
B1: ALL BOOK INFORMATION
B5: BOOKS of COMPUTER
B6: Sr No. | C6: Title of Book | D6: Author | E6: No. of Books | F6: Rack No. | G6: Line No. | I6: Sr No. | J6: Title of Book | K6: Author | L6: No. of Books
B7: 1 | C7: Introduction to Computer Science Using Python | D7: Charles dierbatch | E7: =10-LOSS!E7 -> 2 | F7: A | G7: =RANDBETWEEN(1,2) -> 2 | I7: 1 | J7: =VLOOKUP(I7,$B$6:$G$70,2,0) -> Introduction to Computer Science Using Python | K7: =VLOOKUP(I7,$B$6:$G$70,3,0) -> Charles dierbatch | L7: =VLOOKUP(I7,$B$6:$G$70,4,0) -> 2
B8: 2 | C8: The Hidden Language of Computer Hardware and Software | D8: Charles Petzold | E8: =10-LOSS!E8 -> 6 | F8: A | G8: =RANDBETWEEN(1,2) -> 1 | I8: 5 | J8: =VLOOKUP(I8,$B$6:$G$70,2,0) -> The Pragmetic Programmer | K8: =VLOOKUP(I8,$B$6:$G$70,3,0) -> Andrew Hunt | L8: =VLOOKUP(I8,$B$6:$G$70,4,0) -> 4
B9: 3 | C9: The Good Parts | D9: Douglas Crockford | E9: =10-LOSS!E9 -> 5 | F9: A | G9: =RANDBETWEEN(1,2) -> 1 | I9: 1 | J9: =VLOOKUP(I9,$B$6:$G$70,2,0) -> Introduction to Computer Science Using Python | K9: =VLOOKUP(I9,$B$6:$G$70,3,0) -> Charles dierbatch | L9: =VLOOKUP(I9,$B$6:$G$70,4,0) -> 2
B10: 4 | C10: The Elememts of Computing System | D10: Noam Nisan | E10: =10-LOSS!E10 -> 9 | F10: A | G10: =RANDBETWEEN(1,2) -> 2
B11: 5 | C11: The Pragmetic Programmer | D11: Andrew Hunt | E11: =10-LOSS!E11 -> 4 | F11: A | G11: =RANDBETWEEN(1,2) -> 2
B12: 6 | C12: Structure and Interpretation of computer Programs | D12: Harold Abelson | E12: =10-LOSS!E12 -> 4 | F12: A | G12: =RANDBETWEEN(1,2) -> 1
B13: 7 | C13: Modern opertaing System | D13: Andrew S. Tanenbaum | E13: =10-LOSS!E13 -> 7 | F13: A | G13: =RANDBETWEEN(1,2) -> 1
B14: 8 | C14: Introduction to Algorithms | D14: Thomas H. Cormen | E14: =10-LOSS!E14 -> 7 | F14: A | G14: =RANDBETWEEN(1,2) -> 1
B15: 9 | C15: Programmming Language | D15: Dennis M. Ritchie | E15: =10-LOSS!E15 -> 8 | F15: A | G15: =RANDBETWEEN(1,2) -> 1
B16: 10 | C16: Free Software, Free Society | D16: Richard Stallman | E16: =10-LOSS!E16 -> 2 | F16: A | G16: =RANDBETWEEN(1,2) -> 2
B17: 11 | C17: The C++ Programming Language | D17: Bjarne Stroustrup | E17: =10-LOSS!E17 -> 8 | F17: A | G17: =RANDBETWEEN(1,2) -> 1
B18: 12 | C18: The little Schemer | D18: Dainel P. Friedman | E18: =10-LOSS!E18 -> 6 | F18: A | G18: =RANDBETWEEN(1,2) -> 1
B19: 13 | C19: The Mythical Man-Month | D19: Frederick P. Brooks | E19: =10-LOSS!E19 -> 9 | F19: A | G19: =RANDBETWEEN(1,2) -> 2
B20: 14 | C20: Computer Organization and Design | D20: David A. Patterson | E20: =10-LOSS!E20 -> 4 | F20: A | G20: =RANDBETWEEN(1,2) -> 2
B21: 15 | C21: Progamming Pearls | D21: Jon Bentely | E21: =10-LOSS!E21 -> 4 | F21: A | G21: =RANDBETWEEN(1,2) -> 1
... B26: 20 | C26: Principles and Practice | D26: John F. Hughes | E26: =10-LOSS!E26 -> 6 | F26: A | G26: =RANDBETWEEN(1,2) -> 1
B27: MATH & PHYSICS BOOKS INVENTOY
B28: Sr No. | C28: Title of Book | D28: Author | E28: No. of Books | F28: Rack No. | G28: Line No.
B29: 21 | C29: The Theoratical Minimum | D29: Leonard Susskind | E29: =RANDBETWEEN(1,10) -> 7 | F29: B | G29: =RANDBETWEEN(3,5) -> 5
B30: 22 | C30: A New Kind Of Science | D30: Stephen Wolfarm | E30: =RANDBETWEEN(1,10) -> 3 | F30: B | G30: =RANDBETWEEN(3,5) -> 5
B31: 23 | C31: Our Mathematical Universe | D31: Max tegmark | E31: =RANDBETWEEN(1,10) -> 9 | F31: B | G31: =RANDBETWEEN(3,5) -> 5
B32: 24 | C32: The Theoratical Minimum | D32: Brian Greene | E32: =RANDBETWEEN(1,10) -> 2 | F32: B | G32: =RANDBETWEEN(3,5) -> 3
B33: 25 | C33: A Universe From Nothing | D33: Lawrence krauss | E33: =RANDBETWEEN(1,10) -> 2 | F33: B | G33: =RANDBETWEEN(3,5) -> 4
B34: 26 | C34: A Brief History Of Time | D34: Stephen Hawking | E34: =RANDBETWEEN(1,10) -> 1 | F34: B | G34: =RANDBETWEEN(3,5) -> 3
B35: 27 | C35: The Quantum Universe | D35: Tony Hey | E35: =RANDBETWEEN(1,10) -> 2 | F35: B | G35: =RANDBETWEEN(3,5) -> 4
B36: 28 | C36: The Elegant Universe | D36: Brian Greene | E36: =RANDBETWEEN(1,10) -> 10 | F36: B | G36: =RANDBETWEEN(3,5) -> 5
B37: 29 | C37: Time Reborn | D37: Lee Smolin | E37: =RANDBETWEEN(1,10) -> 8 | F37: B | G37: =RANDBETWEEN(3,5) -> 3
B38: 30 | C38: Physics Of The Impossible | D38: Michio Kaku | E38: =RANDBETWEEN(1,10) -> 8 | F38: B | G38: =RANDBETWEEN(3,5) -> 4
B39: 31 | C39: The Fifth Essence | D39: Lawrence krauss | E39: =RANDBETWEEN(1,10) -> 6 | F39: B | G39: =RANDBETWEEN(3,5) -> 3
B40: 32 | C40: The Grand Design | D40: Stephen Hawking | E40: =RANDBETWEEN(1,10) -> 2 | F40: B | G40: =RANDBETWEEN(3,5) -> 4
... B48: 40 | C48: The Emperor's New Mind | D48: Roger Penrose | E48: =RANDBETWEEN(1,10) -> 9 | F48: B | G48: =RANDBETWEEN(3,5) -> 4
B49: ARTS BOOKS INVENTORY
B50: Sr No. | C50: Title of Book | D50: Author | E50: No. of Books | F50: Rack No. | G50: Line No.
B51: 41 | C51: Classical Art | D51: Aristoi Classical Academy | E51: =RANDBETWEEN(1,10) -> 1 | F51: C | G51: =RANDBETWEEN(6,8) -> 7
B52: 42 | C52: Art History Timeline | D52: Fairfield Suisun | E52: =RANDBETWEEN(1,10) -> 6 | F52: C | G52: =RANDBETWEEN(6,8) -> 7
B53: 43 | C53: African Art | D53: Marsha K Russell | E53: =RANDBETWEEN(1,10) -> 6 | F53: C | G53: =RANDBETWEEN(6,8) -> 7
B54: 44 | C54: The Ancient World | D54: Higher Education Pearson | E54: =RANDBETWEEN(1,10) -> 7 | F54: C | G54: =RANDBETWEEN(6,8) -> 7
...

Sheet B.BOOKS
B2: BORROWED BOOKS
B6: Sr No. | C6: Student ID | D6: Title of Book | E6: Borrow Date | F6: Due Date | G6: Return Date | I6: Sr No. | J6: Title of Book | K6: Student ID
B7: 1 | C7: LGU-BsCs-1 | D7: The Quantum Universe | E7: 44938 | F7: 44969 | G7: 44970 | I7: 8 | J7: =VLOOKUP(I7,$B$6:$G$25,3,0) -> Quantum Aspects Of Life | K7: =VLOOKUP(I7,$B$6:$G$25,2,0) -> LGU-BsCs-8
B8: 2 | C8: LGU-BsCs-2 | D8: The Elegant Universe | E8: 44939 | F8: 44970 | G8: 44972 | I8: 2 | J8: The Elegant Universe | K8: =VLOOKUP(I8,$B$6:$G$25,2,0) -> LGU-BsCs-2
B9: 3 | C9: LGU-BsCs-3 | D9: Time Reborn | E9: 44940 | F9: 44971 | G9: 2/2/2023 | I9: 6 | J9: The Grand Design | K9: =VLOOKUP(I9,$B$6:$G$25,2,0) -> LGU-BsCs-6
B10: 4 | C10: LGU-BsCs-4 | D10: Physics Of The Impossible | E10: 44941 | F10: 44972 | G10: 44970
B11: 5 | C11: LGU-BsCs-5 | D11: The Fifth Essence | E11: 44942 | F11: 44973 | G11: 44975
B12: 6 | C12: LGU-BsCs-6 | D12: The Grand Design | E12: 44943 | F12: 44974 | G12: 44969
B13: 7 | C13: LGU-BsCs-7 | D13: The Fabric Of Reality | E13: 44944 | F13: 44975 | G13: 44981
B14: 8 | C14: LGU-BsCs-8 | D14: Quantum Aspects Of Life | E14: 44945 | F14: 44976 | G14: 44960
B15: 9 | C15: LGU-BsCs-9 | D15: Relation of Political Science | E15: 44946 | F15: 44977 | G15: 44958
B16: 10 | C16: LGU-BsCs-10 | D16: Political Science Influenced | E16: 44947 | F16: 44978 | G16: 44961
B17: 11 | C17: LGU-BsCs-11 | D17: Contemporary Political Theory | E17: 44948 | F17: 44979 | G17: 44985
B18: 12 | C18: LGU-BsCs-12 | D18: Comparative Politics Nature | E18: 44949 | F18: 44980 | G18: 44990
B19: 13 | C19: LGU-BsCs-13 | D19: Leadership Theories | E19: 44950 | F19: 44981 | G19: 44984
B20: 14 | C20: LGU-BsCs-14 | D20: Nature and Scope of Political Science | E20: 44951 | F20: 44982 | G20: 44983
B21: 15 | C21: LGU-BsCs-15 | D21: The Hidden Language of Computer Hardware and Software | E21: 44952 | F21: 44983 | G21: 44998
... B25: 19 | C25: LGU-BsCs-19 | D25: A Handbook of Agile Software Craftsmanship | E25: 44956 | F25: 44987 | G25: 44988

Sheet OVERDUES
B1: OVERDUES
B4: Sr No | C4: Student id | D4: Title of Book | E4: Borrow Date | F4: Due Date | G4: Return Date | H4: P_day charges | I4: Total Charges
B5: 1 | C5: LGU-BSCS-1 | D5: The Quantum Universe | E5: 44938 | F5: 44969 | G5: 44970 | H5: 10 | I5: =(G5-E5)*H5 -> 320
B6: 2 | C6: LGU-BSCS-2 | D6: The Elegant Universe | E6: 44939 | F6: 44970 | G6: 44972 | H6: 10 | I6: =(G6-E6)*H6 -> 330
B7: 3 | C7: LGU-BSCS-3 | D7: Time Reborn | E7: 44940 | F7: 44971 | G7: 2/2/2023 | H7: 10 | I7: =(G7-E7)*H7 -> 190
B8: 4 | C8: LGU-BSCS-4 | D8: Physics Of The Impossible | E8: 44941 | F8: 44972 | G8: 44970 | H8: 10 | I8: =(G8-E8)*H8 -> 290
B9: 5 | C9: LGU-BSCS-5 | D9: The Fifth Essence | E9: 44942 | F9: 44973 | G9: 44975 | H9: 10 | I9: =(G9-E9)*H9 -> 330
B10: 6 | C10: LGU-BSCS-6 | D10: The Grand Design | E10: 44943 | F10: 44974 | G10: 44969 | H10: 10 | I10: =(G10-E10)*H10 -> 260
B11: 7 | C11: LGU-BSCS-7 | D11: The Fabric Of Reality | E11: 44944 | F11: 44975 | G11: 44981 | H11: 10 | I11: =(G11-E11)*H11 -> 370
B12: 8 | C12: LGU-BSCS-8 | D12: Quantum Aspects Of Life | E12: 44945 | F12: 44976 | G12: 44960 | H12: 10 | I12: =(G12-E12)*H12 -> 150
B13: 9 | C13: LGU-BSCS-9 | D13: Relation of Political Science | E13: 44946 | F13: 44977 | G13: 44958 | H13: 10 | I13: =(G13-E13)*H13 -> 120
B14: 10 | C14: LGU-BSCS-10 | D14: Political Science Influenced | E14: 44947 | F14: 44978 | G14: 44961 | H14: 10 | I14: =(G14-E14)*H14 -> 140
B15: 11 | C15: LGU-BSCS-11 | D15: Contemporary Political Theory | E15: 44948 | F15: 44979 | G15: 44985 | H15: 10 | I15: =(G15-E15)*H15 -> 370
B16: 12 | C16: LGU-BSCS-12 | D16: Comparative Politics Nature | E16: 44949 | F16: 44980 | G16: 44990 | H16: 10 | I16: =(G16-E16)*H16 -> 410
B17: 13 | C17: LGU-BSCS-13 | D17: Leadership Theories | E17: 44950 | F17: 44981 | G17: 44984 | H17: 10 | I17: =(G17-E17)*H17 -> 340
B18: 14 | C18: LGU-BSCS-14 | D18: Nature and Scope of Political Science | E18: 44951 | F18: 44982 | G18: 44983 | H18: 10 | I18: =(G18-E18)*H18 -> 320
B19: 15 | C19: LGU-BSCS-15 | D19: The Hidden Language of Computer Hardware and Software | E19: 44952 | F19: 44983 | G19: 44998 | H19: 10 | I19: =(G19-E19)*H19 -> 460
... B23: 19 | C23: LGU-BSCS-19 | D23: A Handbook of Agile Software Craftsmanship | E23: 44956 | F23: 44987 | G23: 44988 | H23: 10 | I23: =(G23-E23)*H23 -> 320

Sheet LOSS
B1: BOOKS DAMAGES
B5: SR NO. | C5: BOOK NAME | D5: DATE OF DAMAGE | E5: NO.OF BOOKS
B6: 1 | C6: The Theoratical Minimum | D6: 2/3/2022 | E6: =RANDBETWEEN(G11,8) -> 5
B7: 2 | C7: Design Patterns | D7: 44746 | E7: =RANDBETWEEN(1,8) -> 8
B8: 3 | C8: Time Reborn | D8: 14/6/2022 | E8: =RANDBETWEEN(1,8) -> 4
B9: 4 | C9: Improving the Design of Existing Code | D9: 24/6/2022 | E9: =RANDBETWEEN(1,8) -> 5
B10: 5 | C10: Heroes of Computer Revolution | D10: 44600 | E10: =RANDBETWEEN(1,8) -> 1
B11: 6 | C11: Principles and Practice | D11: 44601 | E11: =RANDBETWEEN(1,8) -> 6
B12: 7 | C12: Our Mathematical Universe | D12: 44602 | E12: =RANDBETWEEN(1,8) -> 6
B13: 8 | C13: The Theoratical Minimum | D13: 44603 | E13: =RANDBETWEEN(1,8) -> 3
B14: 9 | C14: A Universe From Nothing | D14: 44604 | E14: =RANDBETWEEN(1,8) -> 3
B15: 10 | C15: A Brief History Of Time | D15: 44605 | E15: =RANDBETWEEN(1,8) -> 2
B16: 11 | C16: The Quantum Universe | D16: 44606 | E16: =RANDBETWEEN(1,8) -> 8
B17: 12 | C17: The Elegant Universe | D17: 44607 | E17: =RANDBETWEEN(1,8) -> 2
B18: 13 | C18: Things Political | D18: 1/12/2022 | E18: =RANDBETWEEN(1,8) -> 4
B19: 14 | C19: Political Sciences | D19: 4/12/2022 | E19: =RANDBETWEEN(1,8) -> 1
B20: 15 | C20: Relation of Political Science | D20: 44693 | E20: =RANDBETWEEN(1,8) -> 6
B21: 16 | C21: Political Science Influenced | D21: 13/12/2022 | E21: =RANDBETWEEN(1,8) -> 6
B22: 17 | C22: Contemporary Political Theory | D22: 22/3/2023 | E22: =RANDBETWEEN(1,8) -> 5
B23: 18 | C23: Comparative Politics Nature | D23: 45266 | E23: =RANDBETWEEN(1,8) -> 6
B24: 19 | C24: Leadership Theories | D24: 18/10/2023 | E24: =RANDBETWEEN(1,8) -> 8
B25: 20 | C25: Nature and Scope of Political Science | D25: 21/10/2023 | E25: =RANDBETWEEN(1,8) -> 2
B26: 21 | C26: A confused Mind story | D26: 12/11/2023 | E26: =RANDBETWEEN(1,8) -> 4
B27: 22 | C27: Dreams Meet Delivery | D27: 29/12/2023 | E27: =RANDBETWEEN(1,8) -> 8
